LEVEL  NAME             EXECUTION_ID  TIME_UTC                 LOG
D      alorica_chatbot  fhhqk9t6xcfo  2023-11-27 16:38:44.331  Function execution took 606 ms, finished with status: 'crash'
E      alorica_chatbot  fhhqk9t6xcfo  2023-11-27 16:38:44.330  Traceback (most recent call last):
                                                                 File "/layers/google.python.pip/pip/lib/python3.9/site-packages/flask/app.py", line 2190, in wsgi_app
                                                                   response = self.full_dispatch_request()
                                                                 File "/layers/google.python.pip/pip/lib/python3.9/site-packages/flask/app.py", line 1486, in full_dispatch_request
                                                                   rv = self.handle_user_exception(e)
                                                                 File "/layers/google.python.pip/pip/lib/python3.9/site-packages/flask/app.py", line 1484, in full_dispatch_request
                                                                   rv = self.dispatch_request()
                                                                 File "/layers/google.python.pip/pip/lib/python3.9/site-packages/flask/app.py", line 1469, in dispatch_request
                                                                   return self.ensure_sync(self.view_functions[rule.endpoint])(**view_args)
                                                                 File "/layers/google.python.pip/pip/lib/python3.9/site-packages/functions_framework/__init__.py", line 99, in view_func
                                                                   return function(request._get_current_object())
                                                                 File "/workspace/main.py", line 18, in gcf_alorica_chatbot
                                                                   return alorica_chatbot()
                                                                 File "/workspace/main.py", line 11, in alorica_chatbot
                                                                   response = chatbot_core.process_chatbot_request(request_json)
                                                                 File "/workspace/chatbot_core.py", line 18, in process_chatbot_request
                                                                   response = secret_client.access_secret_version(name=secret_name)
                                                                 File "/layers/google.python.pip/pip/lib/python3.9/site-packages/google/cloud/secretmanager_v1/services/secret_manager_service/client.py", line 1518, in access_secret_version
                                                                   response = rpc(
                                                                 File "/layers/google.python.pip/pip/lib/python3.9/site-packages/google/api_core/gapic_v1/method.py", line 131, in __call__
                                                                   return wrapped_func(*args, **kwargs)
                                                                 File "/layers/google.python.pip/pip/lib/python3.9/site-packages/google/api_core/retry.py", line 372, in retry_wrapped_func
                                                                   return retry_target(
                                                                 File "/layers/google.python.pip/pip/lib/python3.9/site-packages/google/api_core/retry.py", line 207, in retry_target
                                                                   result = target()
                                                                 File "/layers/google.python.pip/pip/lib/python3.9/site-packages/google/api_core/timeout.py", line 120, in func_with_timeout
                                                                   return func(*args, **kwargs)
                                                                 File "/layers/google.python.pip/pip/lib/python3.9/site-packages/google/api_core/grpc_helpers.py", line 77, in error_remapped_callable
                                                                   raise exceptions.from_grpc_error(exc) from exc
                                                               google.api_core.exceptions.PermissionDenied: 403 Permission 'secretmanager.versions.access' denied for resource 'projects/980523551273/secrets/open-ai-key-for-alorica/versions/latest' (or it may not exist).
       alorica_chatbot  fhhqk9t6xcfo  2023-11-27 16:38:44.330  The above exception was the direct cause of the following exception:
       alorica_chatbot  fhhqk9t6xcfo  2023-11-27 16:38:44.330  >
       alorica_chatbot  fhhqk9t6xcfo  2023-11-27 16:38:44.330  	debug_error_string = "UNKNOWN:Error received from peer ipv4:142.250.125.95:443 {grpc_message:"Permission \'secretmanager.versions.access\' denied for resource \'projects/980523551273/secrets/open-ai-key-for-alorica/versions/latest\' (or it may not exist).", grpc_status:7, created_time:"2023-11-27T16:38:44.311499307+00:00"}"
       alorica_chatbot  fhhqk9t6xcfo  2023-11-27 16:38:44.330  	details = "Permission 'secretmanager.versions.access' denied for resource 'projects/980523551273/secrets/open-ai-key-for-alorica/versions/latest' (or it may not exist)."
       alorica_chatbot  fhhqk9t6xcfo  2023-11-27 16:38:44.330  	status = StatusCode.PERMISSION_DENIED
E      alorica_chatbot  fhhqk9t6xcfo  2023-11-27 16:38:44.330  Traceback (most recent call last):
                                                                 File "/layers/google.python.pip/pip/lib/python3.9/site-packages/google/api_core/grpc_helpers.py", line 75, in error_remapped_callable
                                                                   return callable_(*args, **kwargs)
                                                                 File "/layers/google.python.pip/pip/lib/python3.9/site-packages/grpc/_channel.py", line 1161, in __call__
                                                                   return _end_unary_response_blocking(state, call, False, None)
                                                                 File "/layers/google.python.pip/pip/lib/python3.9/site-packages/grpc/_channel.py", line 1004, in _end_unary_response_blocking
                                                                   raise _InactiveRpcError(state)  # pytype: disable=not-instantiable
                                                               grpc._channel._InactiveRpcError: <_InactiveRpcError of RPC that terminated with:
       alorica_chatbot  fhhqk9t6xcfo  2023-11-27 16:38:44.330  [2023-11-27 16:38:44,313] ERROR in app: Exception on / [POST]
D      alorica_chatbot  fhhqk9t6xcfo  2023-11-27 16:38:43.725  Function execution started
D      alorica_chatbot  31ul1vtedli2  2023-11-27 16:29:27.907  Function execution took 27 ms, finished with status: 'crash'
E      alorica_chatbot  31ul1vtedli2  2023-11-27 16:29:27.900  Traceback (most recent call last):
                                                                 File "/layers/google.python.pip/pip/lib/python3.9/site-packages/flask/app.py", line 2190, in wsgi_app
                                                                   response = self.full_dispatch_request()
                                                                 File "/layers/google.python.pip/pip/lib/python3.9/site-packages/flask/app.py", line 1486, in full_dispatch_request
                                                                   rv = self.handle_user_exception(e)
                                                                 File "/layers/google.python.pip/pip/lib/python3.9/site-packages/flask/app.py", line 1484, in full_dispatch_request
                                                                   rv = self.dispatch_request()
                                                                 File "/layers/google.python.pip/pip/lib/python3.9/site-packages/flask/app.py", line 1469, in dispatch_request
                                                                   return self.ensure_sync(self.view_functions[rule.endpoint])(**view_args)
                                                                 File "/layers/google.python.pip/pip/lib/python3.9/site-packages/functions_framework/__init__.py", line 99, in view_func
                                                                   return function(request._get_current_object())
                                                               TypeError: alorica_chatbot() takes 0 positional arguments but 1 was given
       alorica_chatbot  31ul1vtedli2  2023-11-27 16:29:27.900  [2023-11-27 16:29:27,894] ERROR in app: Exception on / [POST]
D      alorica_chatbot  31ul1vtedli2  2023-11-27 16:29:27.879  Function execution started
D      alorica_chatbot  phel3f7v4yo2  2023-11-27 16:25:04.237  Function execution took 312 ms, finished with status: 'crash'
E      alorica_chatbot  phel3f7v4yo2  2023-11-27 16:25:04.236  Traceback (most recent call last):
                                                                 File "/layers/google.python.pip/pip/lib/python3.9/site-packages/flask/app.py", line 2529, in wsgi_app
                                                                   response = self.full_dispatch_request()
                                                                 File "/layers/google.python.pip/pip/lib/python3.9/site-packages/flask/app.py", line 1825, in full_dispatch_request
                                                                   rv = self.handle_user_exception(e)
                                                                 File "/layers/google.python.pip/pip/lib/python3.9/site-packages/flask/app.py", line 1823, in full_dispatch_request
                                                                   rv = self.dispatch_request()
                                                                 File "/layers/google.python.pip/pip/lib/python3.9/site-packages/flask/app.py", line 1799, in dispatch_request
                                                                   return self.ensure_sync(self.view_functions[rule.endpoint])(**view_args)
                                                                 File "/layers/google.python.pip/pip/lib/python3.9/site-packages/functions_framework/__init__.py", line 99, in view_func
                                                                   return function(request._get_current_object())
                                                                 File "/workspace/main.py", line 16, in alorica_chatbot
                                                                   response = secret_client.access_secret_version(name=secret_name)
                                                                 File "/layers/google.python.pip/pip/lib/python3.9/site-packages/google/cloud/secretmanager_v1/services/secret_manager_service/client.py", line 1518, in access_secret_version
                                                                   response = rpc(
                                                                 File "/layers/google.python.pip/pip/lib/python3.9/site-packages/google/api_core/gapic_v1/method.py", line 131, in __call__
                                                                   return wrapped_func(*args, **kwargs)
                                                                 File "/layers/google.python.pip/pip/lib/python3.9/site-packages/google/api_core/retry.py", line 372, in retry_wrapped_func
                                                                   return retry_target(
                                                                 File "/layers/google.python.pip/pip/lib/python3.9/site-packages/google/api_core/retry.py", line 207, in retry_target
                                                                   result = target()
                                                                 File "/layers/google.python.pip/pip/lib/python3.9/site-packages/google/api_core/timeout.py", line 120, in func_with_timeout
                                                                   return func(*args, **kwargs)
                                                                 File "/layers/google.python.pip/pip/lib/python3.9/site-packages/google/api_core/grpc_helpers.py", line 77, in error_remapped_callable
                                                                   raise exceptions.from_grpc_error(exc) from exc
                                                               google.api_core.exceptions.PermissionDenied: 403 Permission 'secretmanager.versions.access' denied for resource 'projects/980523551273/secrets/open-ai-key-for-alorica/versions/latest' (or it may not exist).
       alorica_chatbot  phel3f7v4yo2  2023-11-27 16:25:04.236  The above exception was the direct cause of the following exception:
       alorica_chatbot  phel3f7v4yo2  2023-11-27 16:25:04.236  >
       alorica_chatbot  phel3f7v4yo2  2023-11-27 16:25:04.236  	debug_error_string = "UNKNOWN:Error received from peer ipv4:108.177.111.95:443 {grpc_message:"Permission \'secretmanager.versions.access\' denied for resource \'projects/980523551273/secrets/open-ai-key-for-alorica/versions/latest\' (or it may not exist).", grpc_status:7, created_time:"2023-11-27T16:25:04.217380038+00:00"}"
       alorica_chatbot  phel3f7v4yo2  2023-11-27 16:25:04.235  	details = "Permission 'secretmanager.versions.access' denied for resource 'projects/980523551273/secrets/open-ai-key-for-alorica/versions/latest' (or it may not exist)."
       alorica_chatbot  phel3f7v4yo2  2023-11-27 16:25:04.235  	status = StatusCode.PERMISSION_DENIED
E      alorica_chatbot  phel3f7v4yo2  2023-11-27 16:25:04.235  Traceback (most recent call last):
                                                                 File "/layers/google.python.pip/pip/lib/python3.9/site-packages/google/api_core/grpc_helpers.py", line 75, in error_remapped_callable
                                                                   return callable_(*args, **kwargs)
                                                                 File "/layers/google.python.pip/pip/lib/python3.9/site-packages/grpc/_channel.py", line 1161, in __call__
                                                                   return _end_unary_response_blocking(state, call, False, None)
                                                                 File "/layers/google.python.pip/pip/lib/python3.9/site-packages/grpc/_channel.py", line 1004, in _end_unary_response_blocking
                                                                   raise _InactiveRpcError(state)  # pytype: disable=not-instantiable
                                                               grpc._channel._InactiveRpcError: <_InactiveRpcError of RPC that terminated with:
       alorica_chatbot  phel3f7v4yo2  2023-11-27 16:25:04.235  [2023-11-27 16:25:04,219] ERROR in app: Exception on / [POST]
D      alorica_chatbot  phel3f7v4yo2  2023-11-27 16:25:03.925  Function execution started
E      alorica_chatbot                2023-11-27 16:24:41.101  Traceback (most recent call last):
                                                                 File "/layers/google.python.pip/pip/bin/functions-framework", line 8, in <module>
                                                                   sys.exit(_cli())
                                                                 File "/layers/google.python.pip/pip/lib/python3.9/site-packages/click/core.py", line 1157, in __call__
                                                                   return self.main(*args, **kwargs)
                                                                 File "/layers/google.python.pip/pip/lib/python3.9/site-packages/click/core.py", line 1078, in main
                                                                   rv = self.invoke(ctx)
                                                                 File "/layers/google.python.pip/pip/lib/python3.9/site-packages/click/core.py", line 1434, in invoke
                                                                   return ctx.invoke(self.callback, **ctx.params)
                                                                 File "/layers/google.python.pip/pip/lib/python3.9/site-packages/click/core.py", line 783, in invoke
                                                                   return __callback(*args, **kwargs)
                                                                 File "/layers/google.python.pip/pip/lib/python3.9/site-packages/functions_framework/_cli.py", line 37, in _cli
                                                                   app = create_app(target, source, signature_type)
                                                                 File "/layers/google.python.pip/pip/lib/python3.9/site-packages/functions_framework/__init__.py", line 292, in create_app
                                                                   function = _function_registry.get_user_function(source, source_module, target)
                                                                 File "/layers/google.python.pip/pip/lib/python3.9/site-packages/functions_framework/_function_registry.py", line 41, in get_user_function
                                                                   raise MissingTargetException(
                                                               functions_framework.exceptions.MissingTargetException: File /workspace/main.py is expected to contain a function named alorica_chatbo
D      alorica_chatbot  g96dfamweafv  2023-11-27 15:55:17.545  Function execution took 579 ms, finished with status: 'crash'
E      alorica_chatbot  g96dfamweafv  2023-11-27 15:55:17.543  Traceback (most recent call last):
                                                                 File "/layers/google.python.pip/pip/lib/python3.9/site-packages/flask/app.py", line 2529, in wsgi_app
                                                                   response = self.full_dispatch_request()
                                                                 File "/layers/google.python.pip/pip/lib/python3.9/site-packages/flask/app.py", line 1825, in full_dispatch_request
                                                                   rv = self.handle_user_exception(e)
                                                                 File "/layers/google.python.pip/pip/lib/python3.9/site-packages/flask/app.py", line 1823, in full_dispatch_request
                                                                   rv = self.dispatch_request()
                                                                 File "/layers/google.python.pip/pip/lib/python3.9/site-packages/flask/app.py", line 1799, in dispatch_request
                                                                   return self.ensure_sync(self.view_functions[rule.endpoint])(**view_args)
                                                                 File "/layers/google.python.pip/pip/lib/python3.9/site-packages/functions_framework/__init__.py", line 99, in view_func
                                                                   return function(request._get_current_object())
                                                                 File "/workspace/main.py", line 16, in alorica_chatbot
                                                                   response = secret_client.access_secret_version(name=secret_name)
                                                                 File "/layers/google.python.pip/pip/lib/python3.9/site-packages/google/cloud/secretmanager_v1/services/secret_manager_service/client.py", line 1518, in access_secret_version
                                                                   response = rpc(
                                                                 File "/layers/google.python.pip/pip/lib/python3.9/site-packages/google/api_core/gapic_v1/method.py", line 131, in __call__
                                                                   return wrapped_func(*args, **kwargs)
                                                                 File "/layers/google.python.pip/pip/lib/python3.9/site-packages/google/api_core/retry.py", line 372, in retry_wrapped_func
                                                                   return retry_target(
                                                                 File "/layers/google.python.pip/pip/lib/python3.9/site-packages/google/api_core/retry.py", line 207, in retry_target
                                                                   result = target()
                                                                 File "/layers/google.python.pip/pip/lib/python3.9/site-packages/google/api_core/timeout.py", line 120, in func_with_timeout
                                                                   return func(*args, **kwargs)
                                                                 File "/layers/google.python.pip/pip/lib/python3.9/site-packages/google/api_core/grpc_helpers.py", line 77, in error_remapped_callable
                                                                   raise exceptions.from_grpc_error(exc) from exc
                                                               google.api_core.exceptions.PermissionDenied: 403 Permission 'secretmanager.versions.access' denied for resource 'projects/980523551273/secrets/open-ai-key-for-alorica/versions/latest' (or it may not exist).
       alorica_chatbot  g96dfamweafv  2023-11-27 15:55:17.543  The above exception was the direct cause of the following exception:
       alorica_chatbot  g96dfamweafv  2023-11-27 15:55:17.543  >
       alorica_chatbot  g96dfamweafv  2023-11-27 15:55:17.543  	debug_error_string = "UNKNOWN:Error received from peer ipv4:108.177.121.95:443 {grpc_message:"Permission \'secretmanager.versions.access\' denied for resource \'projects/980523551273/secrets/open-ai-key-for-alorica/versions/latest\' (or it may not exist).", grpc_status:7, created_time:"2023-11-27T15:55:17.51738345+00:00"}"
       alorica_chatbot  g96dfamweafv  2023-11-27 15:55:17.543  	details = "Permission 'secretmanager.versions.access' denied for resource 'projects/980523551273/secrets/open-ai-key-for-alorica/versions/latest' (or it may not exist)."
       alorica_chatbot  g96dfamweafv  2023-11-27 15:55:17.543  	status = StatusCode.PERMISSION_DENIED
E      alorica_chatbot  g96dfamweafv  2023-11-27 15:55:17.543  Traceback (most recent call last):
                                                                 File "/layers/google.python.pip/pip/lib/python3.9/site-packages/google/api_core/grpc_helpers.py", line 75, in error_remapped_callable
                                                                   return callable_(*args, **kwargs)
                                                                 File "/layers/google.python.pip/pip/lib/python3.9/site-packages/grpc/_channel.py", line 1161, in __call__
                                                                   return _end_unary_response_blocking(state, call, False, None)
                                                                 File "/layers/google.python.pip/pip/lib/python3.9/site-packages/grpc/_channel.py", line 1004, in _end_unary_response_blocking
                                                                   raise _InactiveRpcError(state)  # pytype: disable=not-instantiable
                                                               grpc._channel._InactiveRpcError: <_InactiveRpcError of RPC that terminated with:
       alorica_chatbot  g96dfamweafv  2023-11-27 15:55:17.543  [2023-11-27 15:55:17,519] ERROR in app: Exception on / [POST]
D      alorica_chatbot  g96dfamweafv  2023-11-27 15:55:16.966  Function execution started
D      alorica_chatbot  n3hxwqozb3eh  2023-11-27 15:33:21.969  Function execution took 4 ms, finished with status: 'crash'
E      alorica_chatbot  n3hxwqozb3eh  2023-11-27 15:33:21.968  Traceback (most recent call last):
                                                                 File "/layers/google.python.pip/pip/lib/python3.9/site-packages/flask/app.py", line 2529, in wsgi_app
                                                                   response = self.full_dispatch_request()
                                                                 File "/layers/google.python.pip/pip/lib/python3.9/site-packages/flask/app.py", line 1825, in full_dispatch_request
                                                                   rv = self.handle_user_exception(e)
                                                                 File "/layers/google.python.pip/pip/lib/python3.9/site-packages/flask/app.py", line 1823, in full_dispatch_request
                                                                   rv = self.dispatch_request()
                                                                 File "/layers/google.python.pip/pip/lib/python3.9/site-packages/flask/app.py", line 1799, in dispatch_request
                                                                   return self.ensure_sync(self.view_functions[rule.endpoint])(**view_args)
                                                                 File "/layers/google.python.pip/pip/lib/python3.9/site-packages/functions_framework/__init__.py", line 99, in view_func
                                                                   return function(request._get_current_object())
                                                                 File "/workspace/main.py", line 12, in alorica_chatbot
                                                                   user_input = request_json['queryResult']['queryText']
                                                               TypeError: 'Request' object is not subscriptable
       alorica_chatbot  n3hxwqozb3eh  2023-11-27 15:33:21.968  [2023-11-27 15:33:21,968] ERROR in app: Exception on / [POST]
D      alorica_chatbot  n3hxwqozb3eh  2023-11-27 15:33:21.965  Function execution started
D      alorica_chatbot  n3hxm0ag8uc6  2023-11-27 15:33:17.710  Function execution took 32 ms, finished with status: 'crash'
E      alorica_chatbot  n3hxm0ag8uc6  2023-11-27 15:33:17.706  Traceback (most recent call last):
                                                                 File "/layers/google.python.pip/pip/lib/python3.9/site-packages/flask/app.py", line 2529, in wsgi_app
                                                                   response = self.full_dispatch_request()
                                                                 File "/layers/google.python.pip/pip/lib/python3.9/site-packages/flask/app.py", line 1825, in full_dispatch_request
                                                                   rv = self.handle_user_exception(e)
                                                                 File "/layers/google.python.pip/pip/lib/python3.9/site-packages/flask/app.py", line 1823, in full_dispatch_request
                                                                   rv = self.dispatch_request()
                                                                 File "/layers/google.python.pip/pip/lib/python3.9/site-packages/flask/app.py", line 1799, in dispatch_request
                                                                   return self.ensure_sync(self.view_functions[rule.endpoint])(**view_args)
                                                                 File "/layers/google.python.pip/pip/lib/python3.9/site-packages/functions_framework/__init__.py", line 99, in view_func
                                                                   return function(request._get_current_object())
                                                                 File "/workspace/main.py", line 12, in alorica_chatbot
                                                                   user_input = request_json['queryResult']['queryText']
                                                               TypeError: 'Request' object is not subscriptable
       alorica_chatbot  n3hxm0ag8uc6  2023-11-27 15:33:17.706  [2023-11-27 15:33:17,691] ERROR in app: Exception on / [GET]
D      alorica_chatbot  n3hxm0ag8uc6  2023-11-27 15:33:17.678  Function execution started
